<?xml version="1.0"?>
<origin xyz="0 0 -0.125" rpy="1.5708 0 0"/>
<material name="green">
<color rgba="0 1 0 1"/>
</material>
</visual>
<collision>
<origin xyz="0 0 -0.125" rpy="1.5708 0 0"/>
<geometry>
<cylinder length="0.25" radius="0.04"/>
</geometry>
</collision>
</link>


<joint name="arm_joint" type="revolute">
<parent link="base_link"/>
<child link="arm_link"/>
<origin xyz="0 0.18 0.06" rpy="0 0 0"/>
<axis xyz="0 0 1"/>
<limit lower="-1.57" upper="1.0" effort="5.0" velocity="1.0"/>
</joint>


<!-- leg -->
<link name="leg_link">
<inertial>
<mass value="0.7"/>
<inertia ixx="0.003" ixy="0.0" ixz="0.0" iyy="0.003" iyz="0.0" izz="0.003"/>
</inertial>
<visual>
<geometry>
<cylinder length="0.3" radius="0.05"/>
</geometry>
<origin xyz="0 0 -0.15" rpy="1.5708 0 0"/>
<material name="red">
<color rgba="1 0 0 1"/>
</material>
</visual>
<collision>
<origin xyz="0 0 -0.15" rpy="1.5708 0 0"/>
<geometry>
<cylinder length="0.3" radius="0.05"/>
</geometry>
</collision>
</link>


<joint name="leg_joint" type="revolute">
<parent link="base_link"/>
<child link="leg_link"/>
<origin xyz="0 -0.08 0.04" rpy="0 0 0"/>
<axis xyz="1 0 0"/>
<limit lower="-0.7" upper="0.7" effort="10.0" velocity="1.0"/>
</joint>


</robot>